use super::Box;
use core::fmt;
use core::mem;
use core::ptr;

/// An error returned when trying to send on a closed channel. Returned from
/// [`Sender::send`] if the corresponding [`Receiver`] has already been dropped.
///
/// The message that could not be sent can be retreived again with [`SendError::into_inner`].
pub struct SendError<T> {
    channel_ptr: *mut super::Channel<T>,
}

unsafe impl<T: Send> Send for SendError<T> {}

impl<T> SendError<T> {
    pub(crate) const fn new(channel_ptr: *mut super::Channel<T>) -> Self {
        Self { channel_ptr }
    }

    /// Consumes the error and returns the message that failed to be sent.
    #[inline]
    pub fn into_inner(self) -> T {
        // SAFETY: The reference won't be used after it is freed in this method
        let channel: &mut super::Channel<T> = unsafe { &mut *self.channel_ptr };

        // Don't run destructor if we consumed ourselves. Freeing happens here.
        mem::forget(self);

        let message = unsafe { ptr::read(&channel.message).assume_init() };
        unsafe { Box::from_raw(channel) };
        message
    }

    /// Get a reference to the message that failed to be sent.
    #[inline]
    pub fn as_inner(&self) -> &T {
        unsafe { &*(*self.channel_ptr).message.as_ptr() }
    }
}

impl<T> Drop for SendError<T> {
    fn drop(&mut self) {
        // SAFETY: The reference won't be used after it is freed in this method
        let channel: &mut super::Channel<T> = unsafe { &mut *self.channel_ptr };

        unsafe { ptr::drop_in_place(channel.message.as_mut_ptr()) };
        unsafe { Box::from_raw(channel) };
    }
}

impl<T> fmt::Display for SendError<T> {
    fn fmt(&self, f: &mut fmt::Formatter<'_>) -> fmt::Result {
        "sending on a closed channel".fmt(f)
    }
}

impl<T> fmt::Debug for SendError<T> {
    fn fmt(&self, f: &mut fmt::Formatter<'_>) -> fmt::Result {
        write!(f, "SendError<{}>(_)", stringify!(T))
    }
}

impl<T> std::error::Error for SendError<T> {}

/// An error returned from the indefinitely blocking recv functions on a [`Receiver`].
///
/// The recv operation can only fail if the corresponding [`Sender`] was dropped before sending
/// any message. Or if a message has already been sent and received on the channel.
#[derive(Debug, Copy, Clone, Eq, PartialEq, Hash)]
pub struct RecvError;

impl fmt::Display for RecvError {
    fn fmt(&self, f: &mut fmt::Formatter<'_>) -> fmt::Result {
        "receiving on a closed channel".fmt(f)
    }
}

impl std::error::Error for RecvError {}

/// An error returned when trying a non blocking receive on a [`Receiver`].
#[derive(Debug, Copy, Clone, Eq, PartialEq, Hash)]
pub enum TryRecvError {
    /// The channel is still open, but there was no message present in it.
    Empty,

    /// The channel is closed. Either the sender was dropped before sending any message, or the
    /// message has already been extracted from the receiver.
    Disconnected,
}

impl fmt::Display for TryRecvError {
    fn fmt(&self, f: &mut fmt::Formatter<'_>) -> fmt::Result {
        let msg = match self {
            TryRecvError::Empty => "receiving on an empty channel",
            TryRecvError::Disconnected => "receiving on a closed channel",
        };
        msg.fmt(f)
    }
}

impl std::error::Error for TryRecvError {}

/// An error returned when trying a time limited blocking receive on a [`Receiver`].
#[derive(Debug, Copy, Clone, Eq, PartialEq, Hash)]
pub enum RecvTimeoutError {
    /// No message arrived on the channel before the timeout was reached. The channel is still open.
    Timeout,

    /// The channel is closed. Either the sender was dropped before sending any message, or the
    /// message has already been extracted from the receiver.
    Disconnected,
}

impl fmt::Display for RecvTimeoutError {
    fn fmt(&self, f: &mut fmt::Formatter<'_>) -> fmt::Result {
        let msg = match self {
            RecvTimeoutError::Timeout => "timed out waiting on channel",
            RecvTimeoutError::Disconnected => "channel is empty and sending half is closed",
        };
        msg.fmt(f)
    }
}

impl std::error::Error for RecvTimeoutError {}
